<?xml version="1.0" ?>
<!-- 
  This is not a standalone urdf for kobuki. It simply defines the 'kobuki' tag that can
  be incorporated by other urdf files (e.g. turtlebot).
  
  See kobuki_standalone.urdf.xacro for a standalone urdf to be tested with
      kobuki_description/launch/view_model.launch
 -->
<robot name="okrobot" xmlns:xacro="http://ros.org/wiki/xacro">
  <xacro:include filename="$(find okrobot_description)/urdf/common_properties.urdf.xacro"/>
  <xacro:include filename="$(find okrobot_description)/urdf/okrobot_base_gazebo.urdf.xacro"/>

  <property name="M_PI" value="3.14159"/>
  <!-- Okrobot --> 
  <xacro:macro name="okrobot">   
    <link name="base_footprint"/>
    <!--
       Base link is set at the bottom of the base mould.
       This is done to be compatible with the way base link
       was configured for turtlebot 1. Refer to
       
       https://github.com/turtlebot/turtlebot/issues/40
       
       To put the base link at the more oft used wheel
       axis, set the z-distance from the base_footprint
       to 0.352.
      -->
    <joint name="base_joint" type="fixed">
      <origin xyz="0 0 0.066" rpy="0 0 0" />
      <parent link="base_footprint"/>
      <child link="base_link" />
    </joint>
    <link name="base_link">
      <visual>
        <geometry>
          <!-- new mesh -->
          <cylinder length=".08" radius="0.245"/>
        </geometry>
	 <origin xyz="0 0 0" rpy="0 0 0"/>
         <material name="blue">
	 <color rgba="0 0 .8 1"/>
	 </material>
      </visual>
      <collision>
        <geometry>
          <cylinder length="0.08" radius="0.2"/>
        </geometry>
        <origin xyz="0 0 0" rpy="0 0 0"/>
      </collision>
      <inertial>
        <!-- COM experimentally determined -->
        <origin xyz="0.01 0 0"/>
        <mass value="1"/> <!-- 2.4/2.6 kg for small/big battery pack -->
        <!-- Kobuki's inertia tensor is approximated by a cylinder with homogeneous mass distribution
             More details: http://en.wikipedia.org/wiki/List_of_moment_of_inertia_tensors
             m = 2.4 kg; h = 0.09 m; r = 0.175 m
             ixx = 1/12 * m * (3 * r^2 + h^2)
             iyy = 1/12 * m * (3 * r^2 + h^2)
             izz = 1/2 * m * r^2 
          -->
        <inertia ixx="1.0" ixy="0.0" ixz="0.0"
                 iyy="1.0" iyz="0.0" 
                 izz="1.0" />
      </inertial>
    </link>
    




    <joint name="wheel_left_joint" type="continuous">
      <parent link="base_link"/>
      <child link="Okrobot_wheel_left_link"/>
      <origin xyz="0 ${0.352/2} 0.009" rpy="${-M_PI/2} 0 0"/>
      <axis xyz="0 0 1"/>
    </joint>
    <link name="Okrobot_wheel_left_link">
      <visual>
        <geometry>
          <cylinder length="0.04007" radius="0.075"/>
        </geometry>
        <origin xyz="0 0 0" rpy="0 0 0"/>
      </visual>
      <collision>
        <geometry>
          <cylinder length="0.04007" radius="0.075"/>
        </geometry>
        <origin rpy="0 0 0" xyz="0 0 0"/>
      </collision>
      <inertial>
        <mass value="0.05" />
        <origin xyz="0 0 0" />
        <inertia ixx="0.0025" ixy="0.0" ixz="0.0"
                 iyy="0.0025" iyz="0.0" 
                 izz="0.0025" />
      </inertial>
    </link>
    
    <joint name="wheel_right_joint" type="continuous">
      <parent link="base_link"/>
      <child link="Okrobot_wheel_right_link"/>
      <origin xyz="0.00 -${0.352/2} 0.009" rpy="${-M_PI/2} 0 0"/>
      <axis xyz="0 0 1"/>
    </joint>
    <link name="Okrobot_wheel_right_link">
      <visual>
        <geometry>
          <cylinder length="0.04007" radius="0.075"/>
        </geometry>
        <origin xyz="0 0 0" rpy="0 0 0"/>
      </visual>
      <collision>
        <geometry>
          <cylinder length="0.04007" radius="0.075"/>
        </geometry>
        <origin rpy="0 0 0" xyz="0 0 0"/>
      </collision>
      <inertial>
        <mass value="0.05" />
        <origin xyz="0 0 0" />
        <inertia ixx="0.0025" ixy="0.0" ixz="0.0"
                 iyy="0.0025" iyz="0.0" 
                 izz="0.0025" />
      </inertial>
    </link>

    
    <joint name="caster_front_joint" type="fixed">
      <parent link="base_link"/>
      <child link="Okrobot_caster_front_link"/>
      <origin xyz="${0.352/2} 0.0 0.009" rpy="${-M_PI/2} 0 0"/>
    </joint>
    <link name="Okrobot_caster_front_link">
      <collision>
        <geometry>
          <cylinder length="0.04007" radius="0.075"/>
        </geometry>
        <origin rpy="0 0 0" xyz="0 0 0"/>
      </collision>      
      <inertial>
        <mass value="0.05" />
        <origin xyz="0 0 0" />
        <inertia ixx="0.0025" ixy="0.0" ixz="0.0"
                 iyy="0.0025" iyz="0.0" 
                 izz="0.0025" />
      </inertial>
    </link>
    
    <joint name="Okrobot_caster_back_joint" type="fixed">
      <parent link="base_link"/>
      <child link="Okrobot_caster_back_link"/>
      <origin xyz="${-0.352/2} 0.0 0.009" rpy="${-M_PI/2} 0 0"/>
    </joint>
    <link name="Okrobot_caster_back_link">
      <collision>
        <geometry>
          <cylinder length="0.04007" radius="0.075"/>
        </geometry>
        <origin rpy="0 0 0" xyz="0 0 0"/>
      </collision>      
      <inertial>
        <mass value="0.05" />
        <origin xyz="0 0 0" />
        <inertia ixx="0.0025" ixy="0.0" ixz="0.0"
                 iyy="0.0025" iyz="0.0" 
                 izz="0.0025" />
      </inertial>
    </link>
    
    <!-- Kobuki's sensors -->
    <joint name="gyro_joint" type="fixed">
      <axis xyz="0 1 0"/>
      <origin xyz="0.0 0.00 0.04" rpy="0 0 0"/>
      <parent link="base_link"/>
      <child link="gyro_link"/>
    </joint>
    <link name="gyro_link">
      <inertial>
        <mass value="0.001"/>
        <origin xyz="0 0 0" rpy="0 0 0"/>
        <inertia ixx="0.0001" ixy="0" ixz="0" 
                 iyy="0.000001" iyz="0"
                 izz="0.0001"/>
      </inertial>
    </link>

    
    <!-- Kobuki Gazebo simulation details -->
    <okrobot_sim/>
    
  </xacro:macro>
</robot>
